2022-05-13 10:42:47,618 INFO    MainThread:2955350 [wandb_setup.py:_flush():71] setting env: {}
2022-05-13 10:42:47,618 WARNING MainThread:2955350 [wandb_setup.py:_flush():71] could not save program above cwd: /home/tilingl/ehrgraphs/ehrgraphs/scripts/train_recordgraphs.py
2022-05-13 10:42:47,618 INFO    MainThread:2955350 [wandb_setup.py:_flush():71] setting login settings: {}
2022-05-13 10:42:47,618 INFO    MainThread:2955350 [wandb_init.py:_log_setup():371] Logging user logs to /home/tilingl/Pykeen/New_Embedding_Stuff/BA_automatization/wandb/run-20220513_104247-3g9e1rlf/logs/debug.log
2022-05-13 10:42:47,618 INFO    MainThread:2955350 [wandb_init.py:_log_setup():372] Logging internal logs to /home/tilingl/Pykeen/New_Embedding_Stuff/BA_automatization/wandb/run-20220513_104247-3g9e1rlf/logs/debug-internal.log
2022-05-13 10:42:47,618 INFO    MainThread:2955350 [wandb_init.py:init():404] calling init triggers
2022-05-13 10:42:47,618 INFO    MainThread:2955350 [wandb_init.py:init():409] wandb.init called with sweep_config: {}
config: {'_metadata': ContainerMetadata(ref_type=typing.Any, object_type=None, optional=True, key=None, flags={'struct': True}, flags_root=False, resolver_cache=defaultdict(<class 'dict'>, {'now': {('%Y-%m-%d',): '2022-05-13', ('%H-%M-%S',): '10-36-41'}}), key_type=typing.Any, element_type=typing.Any), '_parent': None, '_flags_cache': {'struct': True}, '_content': {'setup': {'entity': 'cardiors', 'project': 'RecordGraphs', 'group': None, 'name': 'emb_run_thesis_NodePiece_t2', 'root': {'charite-hpc': '/sc-projects/sc-proj-ukb-cvd', 'eils-hpc': '/data/analysis/ag-reils/ag-reils-shared/cardioRS'}, 'data_path': 'data/2_datasets_pre/211110_anewbeginning/artifacts', 'output_path': 'results/models', 'use_data_artifact_if_available': True, 'data': {'drop_shortcut_edges': True, 'drop_individuals_without_gp': False, 'min_record_counts': 100}, 'data_identifier': 'WandBGraphDataNoShortcuts_emb1024_min100_leonard_thesis:v0', 'tags': ['leonard_thesis:v0', 'only relation, DeepMLP', '-dim 1024', '32768', 'NodePiece']}, 'head': {'model_type': 'MLP', 'dropout': 0.6728016211425569, 'kwargs': {'num_hidden': 1024, 'num_layers': 1, 'detach_clf': False, 'initial_dropout': 0.2853273875764176}}, 'datamodule': {'covariates': [], 'sampler': {'sampler_type': 'DummySampler'}, 'batch_size': 512, 'partition': 0, 'num_workers': 4, 'label_definition': {'all_cause_death': True, 'phecodes': True, 'custom': []}, 't0_mode': 'recruitment', 'use_top_n_phecodes': 1683, 'edge_weight_threshold': 0.1, 'min_edge_type_fraction': 0.001, 'buffer_years': 0.0, 'filter_input_origins': [], 'load_embeddings_path': '/sc-projects/sc-proj-ukb-cvd/data/2_datasets_pre/220208_graphembeddings/embeddings_leonard/Embedding_dict_NodePiece_t2.feather', 'use_loss_weights': False, 'task': 'tte', 'task_kwargs': {}}, 'model': {'model_type': 'GraphEmbeddings', 'num_hidden': 256, 'num_outputs': 256, 'num_blocks': 3, 'dropout': 0.1, 'weight_norm': True, 'shuffled': False}, 'training': {'exclusions_on_losses': False, 'exclusions_on_metrics': True, 'gradient_checkpointing': False, 'contrastive_loss_factor': 0, 'endpoint_loss_factor': 1, 'vicreg_loss_factor': 0, 'node_dropout': None, 'normalize_node_embeddings': True, 'binarize_records': True, 'write_predictions': False, 'write_embeddings': False, 'write_attributions': False, 'attribution_baseline_mode': 'zeros', 'use_endpoint_embeddings': False, 'patience': 5, 'optimizer_kwargs': {'weight_decay': 0.05082949318285612, 'lr': 0.0002403050945345336}}, 'trainer': {'gpus': [0], 'precision': 16, 'max_epochs': 10000, 'num_sanity_val_steps': -1, 'detect_anomaly': False, 'amp_backend': 'native', 'accumulate_grad_batches': 1}, 'user_config': '/home/tilingl/ehrgraphs/config/experiments/graphembeddings_leonard_thesis_220421.yaml'}}
2022-05-13 10:42:47,618 INFO    MainThread:2955350 [wandb_init.py:init():449] starting backend
2022-05-13 10:42:47,618 INFO    MainThread:2955350 [backend.py:_multiprocessing_setup():95] multiprocessing start_methods=fork,spawn,forkserver, using: spawn
2022-05-13 10:42:47,648 INFO    MainThread:2955350 [backend.py:ensure_launched():199] starting backend process...
2022-05-13 10:42:47,681 INFO    MainThread:2955350 [backend.py:ensure_launched():204] started backend process with pid: 2956966
2022-05-13 10:42:47,683 INFO    MainThread:2955350 [wandb_init.py:init():458] backend started and connected
2022-05-13 10:42:47,686 INFO    MainThread:2955350 [wandb_init.py:init():519] updated telemetry
2022-05-13 10:42:47,689 INFO    MainThread:2955350 [wandb_init.py:init():549] communicating current version
2022-05-13 10:42:51,356 INFO    MainThread:2955350 [wandb_init.py:init():554] got version response upgrade_message: "wandb version 0.12.16 is available!  To upgrade, please run:\n $ pip install wandb --upgrade"

2022-05-13 10:42:51,357 INFO    MainThread:2955350 [wandb_init.py:init():564] communicating run to backend with 30 second timeout
2022-05-13 10:43:19,337 ERROR   Thread-1  :2955350 [retry.py:__call__():126] Retry attempt failed:
Traceback (most recent call last):
  File "/home/tilingl/miniconda3/envs/ehrgraphs2/lib/python3.9/site-packages/urllib3/connectionpool.py", line 445, in _make_request
    six.raise_from(e, None)
  File "<string>", line 3, in raise_from
  File "/home/tilingl/miniconda3/envs/ehrgraphs2/lib/python3.9/site-packages/urllib3/connectionpool.py", line 440, in _make_request
    httplib_response = conn.getresponse()
  File "/home/tilingl/miniconda3/envs/ehrgraphs2/lib/python3.9/http/client.py", line 1371, in getresponse
    response.begin()
  File "/home/tilingl/miniconda3/envs/ehrgraphs2/lib/python3.9/http/client.py", line 319, in begin
    version, status, reason = self._read_status()
  File "/home/tilingl/miniconda3/envs/ehrgraphs2/lib/python3.9/http/client.py", line 280, in _read_status
    line = str(self.fp.readline(_MAXLINE + 1), "iso-8859-1")
  File "/home/tilingl/miniconda3/envs/ehrgraphs2/lib/python3.9/socket.py", line 704, in readinto
    return self._sock.recv_into(b)
  File "/home/tilingl/miniconda3/envs/ehrgraphs2/lib/python3.9/ssl.py", line 1241, in recv_into
    return self.read(nbytes, buffer)
  File "/home/tilingl/miniconda3/envs/ehrgraphs2/lib/python3.9/ssl.py", line 1099, in read
    return self._sslobj.read(len, buffer)
socket.timeout: The read operation timed out

During handling of the above exception, another exception occurred:

Traceback (most recent call last):
  File "/home/tilingl/miniconda3/envs/ehrgraphs2/lib/python3.9/site-packages/requests/adapters.py", line 439, in send
    resp = conn.urlopen(
  File "/home/tilingl/miniconda3/envs/ehrgraphs2/lib/python3.9/site-packages/urllib3/connectionpool.py", line 755, in urlopen
    retries = retries.increment(
  File "/home/tilingl/miniconda3/envs/ehrgraphs2/lib/python3.9/site-packages/urllib3/util/retry.py", line 532, in increment
    raise six.reraise(type(error), error, _stacktrace)
  File "/home/tilingl/miniconda3/envs/ehrgraphs2/lib/python3.9/site-packages/urllib3/packages/six.py", line 770, in reraise
    raise value
  File "/home/tilingl/miniconda3/envs/ehrgraphs2/lib/python3.9/site-packages/urllib3/connectionpool.py", line 699, in urlopen
    httplib_response = self._make_request(
  File "/home/tilingl/miniconda3/envs/ehrgraphs2/lib/python3.9/site-packages/urllib3/connectionpool.py", line 447, in _make_request
    self._raise_timeout(err=e, url=url, timeout_value=read_timeout)
  File "/home/tilingl/miniconda3/envs/ehrgraphs2/lib/python3.9/site-packages/urllib3/connectionpool.py", line 336, in _raise_timeout
    raise ReadTimeoutError(
urllib3.exceptions.ReadTimeoutError: HTTPSConnectionPool(host='api.wandb.ai', port=443): Read timed out. (read timeout=10)

During handling of the above exception, another exception occurred:

Traceback (most recent call last):
  File "/home/tilingl/miniconda3/envs/ehrgraphs2/lib/python3.9/site-packages/wandb/sdk/lib/retry.py", line 102, in __call__
    result = self._call_fn(*args, **kwargs)
  File "/home/tilingl/miniconda3/envs/ehrgraphs2/lib/python3.9/site-packages/wandb/sdk/internal/internal_api.py", line 141, in execute
    return self.client.execute(*args, **kwargs)
  File "/home/tilingl/miniconda3/envs/ehrgraphs2/lib/python3.9/site-packages/wandb/vendor/gql-0.2.0/gql/client.py", line 52, in execute
    result = self._get_result(document, *args, **kwargs)
  File "/home/tilingl/miniconda3/envs/ehrgraphs2/lib/python3.9/site-packages/wandb/vendor/gql-0.2.0/gql/client.py", line 60, in _get_result
    return self.transport.execute(document, *args, **kwargs)
  File "/home/tilingl/miniconda3/envs/ehrgraphs2/lib/python3.9/site-packages/wandb/vendor/gql-0.2.0/gql/transport/requests.py", line 38, in execute
    request = requests.post(self.url, **post_args)
  File "/home/tilingl/miniconda3/envs/ehrgraphs2/lib/python3.9/site-packages/requests/api.py", line 117, in post
    return request('post', url, data=data, json=json, **kwargs)
  File "/home/tilingl/miniconda3/envs/ehrgraphs2/lib/python3.9/site-packages/requests/api.py", line 61, in request
    return session.request(method=method, url=url, **kwargs)
  File "/home/tilingl/miniconda3/envs/ehrgraphs2/lib/python3.9/site-packages/requests/sessions.py", line 542, in request
    resp = self.send(prep, **send_kwargs)
  File "/home/tilingl/miniconda3/envs/ehrgraphs2/lib/python3.9/site-packages/requests/sessions.py", line 655, in send
    r = adapter.send(request, **kwargs)
  File "/home/tilingl/miniconda3/envs/ehrgraphs2/lib/python3.9/site-packages/requests/adapters.py", line 529, in send
    raise ReadTimeout(e, request=request)
requests.exceptions.ReadTimeout: HTTPSConnectionPool(host='api.wandb.ai', port=443): Read timed out. (read timeout=10)
2022-05-13 10:43:21,357 INFO    MainThread:2955350 [interface_queue.py:_communicate_run():336] couldn't get run from backend
2022-05-13 10:43:21,357 ERROR   MainThread:2955350 [wandb_init.py:init():569] backend process timed out
2022-05-13 10:43:21,357 ERROR   MainThread:2955350 [wandb_init.py:init():578] encountered error: Error communicating with wandb process
try: wandb.init(settings=wandb.Settings(start_method='fork'))
or:  wandb.init(settings=wandb.Settings(start_method='thread'))
For more info see: https://docs.wandb.ai/library/init#init-start-error
2022-05-13 10:44:23,520 INFO    MainThread:2955350 [wandb_init.py:teardown():219] tearing down wandb.init
