2022-05-13 10:42:51,236 INFO    MainThread:2956966 [internal.py:wandb_internal():87] W&B internal server running at pid: 2956966, started at: 2022-05-13 10:42:51.233777
2022-05-13 10:42:51,238 DEBUG   HandlerThread:2956966 [handler.py:handle_request():130] handle_request: check_version
2022-05-13 10:42:51,238 INFO    WriterThread:2956966 [datastore.py:open_for_write():77] open: /home/tilingl/Pykeen/New_Embedding_Stuff/BA_automatization/wandb/run-20220513_104247-3g9e1rlf/run-3g9e1rlf.wandb
2022-05-13 10:42:51,247 DEBUG   SenderThread:2956966 [sender.py:send():238] send: header
2022-05-13 10:42:51,247 DEBUG   SenderThread:2956966 [sender.py:send_request():252] send_request: check_version
2022-05-13 10:42:51,358 DEBUG   SenderThread:2956966 [sender.py:send():238] send: run
2022-05-13 10:42:51,367 INFO    SenderThread:2956966 [sender.py:_maybe_setup_resume():505] checking resume status for cardiors/RecordGraphs/3g9e1rlf
2022-05-13 10:43:21,358 DEBUG   HandlerThread:2956966 [handler.py:handle_request():130] handle_request: shutdown
2022-05-13 10:43:21,359 INFO    HandlerThread:2956966 [handler.py:finish():731] shutting down handler
2022-05-13 10:43:21,360 INFO    WriterThread:2956966 [datastore.py:close():281] close: /home/tilingl/Pykeen/New_Embedding_Stuff/BA_automatization/wandb/run-20220513_104247-3g9e1rlf/run-3g9e1rlf.wandb
2022-05-13 10:43:24,740 ERROR   SenderThread:2956966 [retry.py:__call__():126] Retry attempt failed:
Traceback (most recent call last):
  File "/home/tilingl/miniconda3/envs/ehrgraphs2/lib/python3.9/site-packages/urllib3/connectionpool.py", line 445, in _make_request
    six.raise_from(e, None)
  File "<string>", line 3, in raise_from
  File "/home/tilingl/miniconda3/envs/ehrgraphs2/lib/python3.9/site-packages/urllib3/connectionpool.py", line 440, in _make_request
    httplib_response = conn.getresponse()
  File "/home/tilingl/miniconda3/envs/ehrgraphs2/lib/python3.9/http/client.py", line 1371, in getresponse
    response.begin()
  File "/home/tilingl/miniconda3/envs/ehrgraphs2/lib/python3.9/http/client.py", line 319, in begin
    version, status, reason = self._read_status()
  File "/home/tilingl/miniconda3/envs/ehrgraphs2/lib/python3.9/http/client.py", line 280, in _read_status
    line = str(self.fp.readline(_MAXLINE + 1), "iso-8859-1")
  File "/home/tilingl/miniconda3/envs/ehrgraphs2/lib/python3.9/socket.py", line 704, in readinto
    return self._sock.recv_into(b)
  File "/home/tilingl/miniconda3/envs/ehrgraphs2/lib/python3.9/ssl.py", line 1241, in recv_into
    return self.read(nbytes, buffer)
  File "/home/tilingl/miniconda3/envs/ehrgraphs2/lib/python3.9/ssl.py", line 1099, in read
    return self._sslobj.read(len, buffer)
socket.timeout: The read operation timed out

During handling of the above exception, another exception occurred:

Traceback (most recent call last):
  File "/home/tilingl/miniconda3/envs/ehrgraphs2/lib/python3.9/site-packages/requests/adapters.py", line 439, in send
    resp = conn.urlopen(
  File "/home/tilingl/miniconda3/envs/ehrgraphs2/lib/python3.9/site-packages/urllib3/connectionpool.py", line 755, in urlopen
    retries = retries.increment(
  File "/home/tilingl/miniconda3/envs/ehrgraphs2/lib/python3.9/site-packages/urllib3/util/retry.py", line 532, in increment
    raise six.reraise(type(error), error, _stacktrace)
  File "/home/tilingl/miniconda3/envs/ehrgraphs2/lib/python3.9/site-packages/urllib3/packages/six.py", line 770, in reraise
    raise value
  File "/home/tilingl/miniconda3/envs/ehrgraphs2/lib/python3.9/site-packages/urllib3/connectionpool.py", line 699, in urlopen
    httplib_response = self._make_request(
  File "/home/tilingl/miniconda3/envs/ehrgraphs2/lib/python3.9/site-packages/urllib3/connectionpool.py", line 447, in _make_request
    self._raise_timeout(err=e, url=url, timeout_value=read_timeout)
  File "/home/tilingl/miniconda3/envs/ehrgraphs2/lib/python3.9/site-packages/urllib3/connectionpool.py", line 336, in _raise_timeout
    raise ReadTimeoutError(
urllib3.exceptions.ReadTimeoutError: HTTPSConnectionPool(host='api.wandb.ai', port=443): Read timed out. (read timeout=10)

During handling of the above exception, another exception occurred:

Traceback (most recent call last):
  File "/home/tilingl/miniconda3/envs/ehrgraphs2/lib/python3.9/site-packages/wandb/sdk/lib/retry.py", line 102, in __call__
    result = self._call_fn(*args, **kwargs)
  File "/home/tilingl/miniconda3/envs/ehrgraphs2/lib/python3.9/site-packages/wandb/sdk/internal/internal_api.py", line 141, in execute
    return self.client.execute(*args, **kwargs)
  File "/home/tilingl/miniconda3/envs/ehrgraphs2/lib/python3.9/site-packages/wandb/vendor/gql-0.2.0/gql/client.py", line 52, in execute
    result = self._get_result(document, *args, **kwargs)
  File "/home/tilingl/miniconda3/envs/ehrgraphs2/lib/python3.9/site-packages/wandb/vendor/gql-0.2.0/gql/client.py", line 60, in _get_result
    return self.transport.execute(document, *args, **kwargs)
  File "/home/tilingl/miniconda3/envs/ehrgraphs2/lib/python3.9/site-packages/wandb/vendor/gql-0.2.0/gql/transport/requests.py", line 38, in execute
    request = requests.post(self.url, **post_args)
  File "/home/tilingl/miniconda3/envs/ehrgraphs2/lib/python3.9/site-packages/requests/api.py", line 117, in post
    return request('post', url, data=data, json=json, **kwargs)
  File "/home/tilingl/miniconda3/envs/ehrgraphs2/lib/python3.9/site-packages/requests/api.py", line 61, in request
    return session.request(method=method, url=url, **kwargs)
  File "/home/tilingl/miniconda3/envs/ehrgraphs2/lib/python3.9/site-packages/requests/sessions.py", line 542, in request
    resp = self.send(prep, **send_kwargs)
  File "/home/tilingl/miniconda3/envs/ehrgraphs2/lib/python3.9/site-packages/requests/sessions.py", line 655, in send
    r = adapter.send(request, **kwargs)
  File "/home/tilingl/miniconda3/envs/ehrgraphs2/lib/python3.9/site-packages/requests/adapters.py", line 529, in send
    raise ReadTimeout(e, request=request)
requests.exceptions.ReadTimeout: HTTPSConnectionPool(host='api.wandb.ai', port=443): Read timed out. (read timeout=10)
2022-05-13 10:44:19,853 INFO    SenderThread:2956966 [dir_watcher.py:__init__():169] watching files in: /home/tilingl/Pykeen/New_Embedding_Stuff/BA_automatization/wandb/run-20220513_104247-3g9e1rlf/files
2022-05-13 10:44:19,854 INFO    SenderThread:2956966 [sender.py:_start_run_threads():825] run started: 3g9e1rlf with start time 1652431367
2022-05-13 10:44:19,854 INFO    SenderThread:2956966 [sender.py:finish():1091] shutting down sender
2022-05-13 10:44:19,854 INFO    SenderThread:2956966 [dir_watcher.py:finish():283] shutting down directory watcher
2022-05-13 10:44:20,855 INFO    SenderThread:2956966 [dir_watcher.py:finish():313] scan: /home/tilingl/Pykeen/New_Embedding_Stuff/BA_automatization/wandb/run-20220513_104247-3g9e1rlf/files
2022-05-13 10:44:20,856 INFO    SenderThread:2956966 [dir_watcher.py:finish():327] scan save: /home/tilingl/Pykeen/New_Embedding_Stuff/BA_automatization/wandb/run-20220513_104247-3g9e1rlf/files/config.yaml config.yaml
2022-05-13 10:44:20,856 INFO    SenderThread:2956966 [file_pusher.py:finish():177] shutting down file pusher
2022-05-13 10:44:20,856 INFO    SenderThread:2956966 [file_pusher.py:join():182] waiting for file pusher
2022-05-13 10:44:23,379 INFO    MainThread:2956966 [internal.py:handle_exit():77] Internal process exited
